Workbook
Name _ftn1: '(4) E&S Assessment'!$A$3
Name _ftnref1: '(4) E&S Assessment'!#REF!
Name Beg_Bal: 'Loan Amortization Schedule'!$C$18:$C$497
Name Bullet: '[1]General Information'!$C$95
Name Cash_minimum: #REF!
Name Cash_minimum: #REF!
Name Cash_minimum: #REF!
Name Cash_minimum: #REF!
Name Cash_minimum: #REF!
Name Company_Name: #REF!
Name Company_Name: #REF!
Name Company_Name: #REF!
Name Company_Name: #REF!
Name Company_Name: #REF!
Name Cum_Int: 'Loan Amortization Schedule'!$J$18:$J$497
Name Data: 'Loan Amortization Schedule'!$A$18:$J$497
Name End_Bal: 'Loan Amortization Schedule'!$I$18:$I$497
Name Extra_Pay: 'Loan Amortization Schedule'!$E$18:$E$497
Name FinPrep: [2]Keys!$B$89:$B$92
Name freq: '[3]Cover Sheet'!$D$30
Name Full_Print: 'Loan Amortization Schedule'!$A$1:$J$497
Name Header_Row: ROW('Loan Amortization Schedule'!$17:$17)
Name Int: 'Loan Amortization Schedule'!$H$18:$H$497
Name Int_basis: #REF!
Name Interest_Rate: 'Loan Amortization Schedule'!$D$6
Name Last_Row: IF(Values_Entered,Header_Row+Number_of_Payments,Header_Row)
Name Loan_Amount: 'Loan Amortization Schedule'!$D$5
Name Loan_Start: 'Loan Amortization Schedule'!$D$9
Name Loan_Years: 'Loan Amortization Schedule'!$D$7
Name none: #REF!
Name none: #REF!
Name none: #REF!
Name none: #REF!
Name none: #REF!
Name Num_Pmt_Per_Year: 'Loan Amortization Schedule'!$D$8
Name Number_of_Payments: MATCH(0.01,End_Bal,-1)+1
Name Pay_Date: 'Loan Amortization Schedule'!$B$18:$B$497
Name Pay_Num: 'Loan Amortization Schedule'!$A$18:$A$497
Name Payment_Date: DATE(YEAR(Loan_Start),MONTH(Loan_Start)+Payment_Number,DAY(Loan_Start))
Name Princ: 'Loan Amortization Schedule'!$G$18:$G$497
Name Print_Area_Reset: OFFSET(Full_Print,0,0,Last_Row)
Name Sched_Pay: 'Loan Amortization Schedule'!$D$18:$D$497
Name Scheduled_Extra_Payments: 'Loan Amortization Schedule'!$D$10
Name Scheduled_Interest_Rate: 'Loan Amortization Schedule'!$D$6
Name Scheduled_Monthly_Payment: 'Loan Amortization Schedule'!$J$5
Name Sector: [4]MenuMaster!$E$6:$E$10
Name Start_date: #REF!
Name Start_date: #REF!
Name Start_date: #REF!
Name Start_date: #REF!
Name Start_date: #REF!
Name Stock_Inventory: #REF!
Name Stock_Inventory: #REF!
Name Stock_Inventory: #REF!
Name Stock_Inventory: #REF!
Name Stock_Inventory: #REF!
Name TERM: '[4]Cover Sheet'!$D$30
Name Total_Interest: 'Loan Amortization Schedule'!$J$9
Name Total_Pay: 'Loan Amortization Schedule'!$F$18:$F$497
Name Values_Entered: IF(Loan_Amount*Interest_Rate*Loan_Years*Loan_Start>0,1,0)

Sheet Intro
B2: Steps to complete the appraisal tool
B4: General information | C4: This is a semi automated excel tool. Data should only be encoded in yellow colored cells. Gray cells are protected and hence no data entry is accepted.
C5: cell color | D5: You need to encode data to cells with this color. Do not leave such cells blank.
C6: cell color | D6: Protected area: no data entry is accepted
C7: The tool has 7 sheets-numbered from 1-7. Sheet 1 contains basic client, business and loan information. Sheet 2 contains qualitative assessment and sheets 3 contain financial analysis including month-by-month cashflow. Sheet 4 contains environmental and social impact analysis of the business under review. Sheet 4 is dedicated for social and environmental assessment. it is a checklist to be completed by observing the business and interviewing the client. sheet 5 contains information entry on proposed collateral by the client. Sheet 6 presents summary of the qualitative and quantitative assessment with proposed loan decision. Sheet 7 is automated sheet used for calculation of loan and interest rapuemnt based on parameters encoded in sheet 1.
B8: Step1 | C8: complete basic information sheet. This contains basic information on the applicant and the business including loan request and its breakdown by purpose. Loan purpose is what the borrower plans to buy with the loan requested and owner contribution. Some consistency checks of encoded data is included.
B9: Step2 | C9: Conduct business and character assessment by filling "(2) Bus.&Character assess" sheet. Start with listing credit history and rate the MSME using the 10 factors listed. Note: rating to be given for each factor needs to be well justified by writing notes and observations in the comments section for each of the factors rated. Ratings will be invalid unless it is well justified.
C10: Qualitative assessment is scored out of 100. Applicant need to score over 75% to qualify for a loan. The tool alarms if borrower fails to pass the qualitative assessment as the loan appraisal shouldn't be continued.
B11: Step3 | C11: 1) start by completing Sales and purchase summary section on sheet (3)-Cash flow Analysis. First list major sales and purchase(raw material) items. indicate what % of the sales and purchases are made on credit. sales and purchase data can be encoded per day, week or month. hence choose the option that suits to the data collected as per convenience to the customers. include ending inventories for sales as well as purchase items to complete the section. Ending inventory refers to stocks of finished goods and raw materials and work in progress at the time of business visits. Complete percentage of credit and cash sales/ purchases in the spaces provided. the rest of the data will be automatically calculated and taken to respective places in balance sheet and income statement.
C12: 2) Go to Income statement section and complete missing information's in yellow colored cells. Please encode annual figures.
C13: 3) Complete the balance sheet data on yellow shaded cells. Then proceed to complete the expected growth rates for major items. Scroll to projected cash flow section and complete missing information, shaded yellow. Cash flow from operation is automatically filled. Complete seasonality information found at the top of the cash flow table. Months with average sales are given 100%, peak sales months will be above 100% and low sales months will be below 100%. Ex. If average sales is 10,000 and applicant informs you that during peak months sales raises to 12,000 and drops to 8000 during low months, you put 100% for average months, 120% for peak months and 80% for low months. cash flow from operation is automatically calculated and you need to encoded data relating to financing, investing and other activities in the respective sections of the cash flow statement. please encode inflows as a positive figure and outflows as negative figures.
B14: Step 4 | C14: Go to (4) E&S assessment sheet and complete the environmental and social screening checklist. Don not forget to write corrective action plans if you notice some incompliances.
B15: Step 5 | C15: Complete (5) Collateral Worksheet based on information obtained from the applicant.
B16: Step 6 | C16: Go to sheet (6) Summary and Decision sheet. You have now completed your assessment and ready to make lending decision. The tool will help you to summarize qualitative, quantitative, E&S, and collateral assessments and propose lending decision. All the four lending criteria need to be fulfilled.
B17: Step 7 | C17: You can do scenario analysis by changing loan parameters or key assumptions. See the impact on cash flow of changing loan parameters and choose the best fit.

Sheet (1)Basic Info and loan request
B1: CLIENT AND BUSINESS INFORMATION SHEET
B3: Business Name | C3: tkus café and restourant | E3: Analyst | F3: kibret | G3: Date | H3: 16/11/23
B4: Loan Product | C4: WEDP | E4: Branch Name | F4: mekelle
B5: Application/ WEDP ID | C5: xxxx
B7: PERSONAL INFORMATION (Ref. Application form ser no.1)
C8: First | D8: Father's Name | E8: G.Fathers's Name
B9: Applicant Name | C9: meron | D9: dagne | E9: markos | F9: TIN No. | G9: XXXX | H9: Gender | I9: Female
B11: Spouse Name | E11: Spouse occupation
B14: Home Address | C14: meneharia sub city kebele 5 | G14: Phone | H14: xxxx
B16: Marital Status | C16: Widowed | E16: Education level | F16: Secondary | G16: Age | H16: 32
B18: BUSINESS INFORMATION (Ref. Application form ser no.2)
B20: Business Description | C20: café and restorant | F20: Peak Sales Months | H20: N/A
F21: Lowest Sales Months | H21: N/A
B24: Business Address | C24: café and restorant
B26: Number Business Owners/Partners | C26: 1 | D26: # of women owners | E26: 1 | F26: Percentage of women owners | G26: =E26/C26 -> 1 | H26: Date Business Started | I26: oct,2016
B28: Form of ownership | C28: Sole Propritership
B31: Economic Sector | C31: Service | D31: Subsector Activity | E31: café and restaurant
C34: Current | D34: #women | E34: Planned(cummulative)
B35: Full time employees: | C35: 8 | D35: 5 | E35: 13 | F35: Total # of Hrs Worked by part time and seasonal employees per month
B36: Partime Employees
B37: Seasonal Employees | H37: FT Equivalent
B38: Famliy Members Employed | H38: =H36/(56*52) -> 0
F39: #of Dependants | H39: 4
B40: LOAN REQUESTED BY CLIENT (Ref. application form ser no.3)
B42: Loan Request | C42: 1200000 | E42: Annual interest rate | F42: 0.18
D43: Repayment frequency
B44: Term (in Months) | C44: 24 | D44: Monthly | E44: Interest basis | F44: Declining
B46: Cash contribution | C46: 0 | D46: =C46/C42 -> 0 | E46: Instalments/yr. | F46: =IF(D44="","",IF(D44="Weekly",48,IF(D44="Bi-weekly",24,IF(D44="monthly",12,IF(D44="Quarterly",4,2))))) -> 12
B48: Grace period Requested (months) | E48: Total instalments | F48: =(C44/12)*F46-C48 -> 24
B49: Interest Only Months
E50: %
B51: Loan Purpose | C51: Working capital | D51: 540000 | E51: =D51/(C42+C46)*100% -> 0.45 | F51: =IF((D51+D52)=(C42+C46), "OK", "ERROR") -> OK
C52: Investment(fixed asset) | D52: 660000 | E52: =D52/(C42+C46)*100% -> 0.55
B54: PURPOSE OF THE LOAN - PROJECT COST (Ref. application form ser.no 3.8 ሀ፣ ለ፤ሐ)
B55: Items to be Purchased/Financed | C55: Quantity | D55: unit price (ETB) | E55: Value
B56: 1. Working Capital
B57: bulk purchase | C57: 2 | D57: 130000 | E57: =C57*D57 -> 260000
B58: vegetables | C58: 1 | D58: 140000 | E58: =C58*D58 -> 140000
B59: rent | C59: 6 | D59: 5000 | E59: =C59*D59 -> 30000
E60: =C60*D60 -> 0
...

Sheet (2)Bus. and Character Assess.
B1: BUSINESS & CHARACTER ASSESSMENT SHEET
B3: CREDIT HISTORY & CURRENT EXPOSURE
B5: NBE Credit Report Obtained (Y/N?) | C5: No
B6: Total Number of Repaid Loans | C6: 3
B8: CREDIT and REPAYMENT HISTORY (Ref. application form ser.no 4) | J8: Score | R8: Repayment | T8: Score
B9: Lender/ Lessor | C9: Date Received | D9: Loan/Lease Amount | E9: Current Balance | F9: Maturity date | G9: Loan / Lease Purpose | H9: Status | I9: Letter from Lender | R9: Regular | T9: 3
B10: hope mfi | D10: 200000 | E10: 0 | G10: Working capital | H10: Settled on time | I10: Yes | J10: =IF(H10=$R$9,$T$9,IF(H10=$R$10,$T$10,IF(H10=$R$11,$T$11,IF(H10=$R$12,$T$12,IF(H10=$R$13,$T$13,IF(H10=$R$14,0,"")))))) -> 5 | K10: =IF(H10="Defaulted","Do not Proceed","") | R10: Settled on time | T10: 5
B11: hope mfi | D11: 300000 | E11: 0 | G11: Working capital | H11: Settled on time | I11: Yes | J11: =IF(H11=$R$9,$T$9,IF(H11=$R$10,$T$10,IF(H11=$R$11,$T$11,IF(H11=$R$12,$T$12,IF(H11=$R$13,$T$13,IF(H11=$R$14,0,"")))))) -> 5 | R11: Settled late | T11: 0
H12: Max score | I12: 10 | J12: =IF(H12=$R$9,$T$9,IF(H12=$R$10,$T$10,IF(H12=$R$11,$T$11,IF(H12=$R$12,$T$12,IF(H12=$R$13,$T$13,""))))) | K12: =IF(H11="Defaulted","Do not Proceed","") | R12: Irregular | T12: -5
H13: Achieved | I13: =J10+J11 -> 10 | J13: =IF(H13=$R$9,$T$9,IF(H13=$R$10,$T$10,IF(H13=$R$11,$T$11,IF(H13=$R$12,$T$12,IF(H13=$R$13,$T$13,""))))) | R13: Defaulted | T13: -15
R14: None | T14: 0
B15: BUSINESS & CHARACTER ASSESSMENT/ RISK PROFILE (from application review and site visit) | J15: Score
B18: Years of business operation (Ref. application form ser.no. 2.5 and loan application date) | C18: > 24 months | D18: Observation/ Justification | E18: the beusness has operated for the past 20 years unlicensed but, 5 years with license | J18: =IF(C18=F66,G66,IF(C18=F67,G67,IF(C18=F68,G68,IF(C18=F69,G69,0)))) -> 10 | K18: =IF(E18<>"","OK", "INVALID") -> OK
A19: What to look for | B19: Businesses with more than 2 years in operation are relatively less riskier
B21: Management Competence (Ref. application form ser.no. 5) | C21: Competent/ well performing | D21: Observation/ Justification | E21: she is well respected by her customers as well as by er employees. | J21: =IF(C21=C56,D56,IF(C21=C57,D57,IF(C21=C58,D58))) -> 15 | K21: =IF(E21<>"","OK", "INVALID") -> OK
A22: What to look for | B22: Average: experienced in the business(>2yrs), 10+ formal education, managing growing business, have basic knowledge about markets, risks and competitors, Competent: if exceed average in any of the factors listed.Poor-if below average in any factor listed.
B24: Supplier quality (Ref. application form ser no. 7) | C24: Satisfactory/ Adequate supply chain | D24: Observation/ Justification | E24: she has long and good relasionship with suppliers due to this good relationship she maneged to get very scarese raw materials easily. | J24: =IF(C24=C61,D61,IF(C24=C62,D62,IF(C24=C63,D63))) -> 9 | K24: =IF(E24<>"","OK", "INVALID") -> OK | X24: Management Competence
A25: What to look for | B25: Average: Have atleast two regular suppliers, get delivery on time with the requested quantity and quality, quality meet the expectations of the client, there are other supply sources otherthan the main suppliers (Plan B) in case of delivery failures. Very relaible- if exceeding average in any of the factors listed, or additional skills observed, Unrelaible-if achieved below average in any of the listed factors | X25: Very competent | Y25: 5
X26: Average | Y26: 3
B27: Sales Prospects/ Market Suitability (Ref. application form ser.no. 8) | C27: Very good/ High demand projection | D27: Observation/ Justification | E27: the busines is wellexprienced as wellas it located in down townwith many offices and males and also nerest tomarket place. | J27: =IF(C27=C66,D66,IF(C27=C67,D67,IF(C27=C68,D68))) -> 15 | K27: =IF(E27<>"","OK", "INVALID") -> OK | X27: Poor | Y27: 0
A28: What to look for | B28: Adequate demand projection:Relaible customer base (as observed/assessed), diversified, Offer quality products/services based on observation and cusomter feedback, offering competitive price for goods/services (check against similar businesses), Located in market place, have clear marketing strategy and good access to markets, acceptable competition and market risk, etc. High dd projection-if exceeding average in any of the factors listed or additional market potential observed. Unrelaible DD Projection-if rated below average in any of the rating factors
X29: Supplier quality
B30: Project plan (Preparation)-Ref. application form ser.no.3.1 to 3.8 | C30: Well planned | D30: Observation/ Justification | E30: she planning to renovte the restaurant and expand thebusnest and to diversified her services. | J30: =IF(C30=C71,D71,IF(C30=C72,D72,IF(C30=C73,D73))) -> 10 | K30: =IF(E30<>"","OK", "INVALID") -> OK | X30: Very reliable | Y30: 5
A31: What to look for | B31: Well planned: if there is a clear & detailed plan; awareness of risks; mitigation plans; logical & precise explanations; ease & familiarity with implementation requirements (manpower requirement, demand, raw material supply, financing source, etc); "Plan B" strategy; well prepared to implement (skills, staff, tools).Some gaps: if details are not worked out in some areas. Unclear-if no clear breakdown of planned activity is communicated/available. | X31: Satisfactory | Y31: 3
X32: Unreliable | Y32: 0
B33: Savings record-( (Ref. application form ser.no. 10 and 9) | C33: Some savings habit | D33: Observation/ Justification | E33: she has cash at bank 500000.00 but not verfied. | J33: =IF(C33=C76,D76,IF(C33=C77,D77,IF(C33=C78,D78))) -> 3 | K33: =IF(E33<>"","OK", "INVALID") -> OK
B34: To qualify for "Regular", deposits should have been made regularly in the past 3 months and/or having active membership in an ongogin equb scheme. Some savings habit-have irregualr deposit in a financial institution, was member in equb closed three months ago, invested in movable/immovable assets. No savings habit-if not able to establsh any savings activities either in formal FIs or infomrmal saving schemes. | X34: Sales prospects
A35: What to look for | X35: Poor | Y35: 0
X37: Project idea/plan
X38: Well planned | Y38: 5
B39: =[5]Keys!A67 -> Responsiveness | C39: Cooperative/shared all relevant info/doc | D39: Observation/ Justification | E39: she is very rsponcive and cooperative. | J39: =IF(C39=C79,D79,IF(C39=C80,D80,IF(C39=C81,D81))) -> 5 | K39: =IF(E39<>"","OK", "INVALID") -> OK | X39: Some detail gaps | Y39: 3
A40: What to look for | B40: Cooperative-Answers questions willingly & thoughtfully; freely shares information & accounts; enthusiastic about business; listens carefully; demonstrates understanding & patience about assessment process; attentive & focused.Average-shared some documents but hesitant to share some information. Not Willing-if uncooperative in interview process and failed to share critical docuemnts requested. | X40: Very unclear | Y40: 0
A42: What to look for | B42: Record Keeping and asset management (Ref. Application Form ser.no.6) | C42: Basic record keeping | D42: Observation/ Justification | E42: she records daily but not properly | J42: =IF(C42=C82,D82,IF(C42=C83,D83,IF(C42=C84,D84))) -> 5 | K42: =IF(E42<>"","OK", "INVALID") -> OK | X42: Character
B43: Financial record all in order-Accounting books up-to-date & complete; receipts organized & filed; assets well cared for & organized; premises neat & maintained;Basic record keeping-if basic daily sales and expenses, purchase record, recievable and payables recorded.Inconsistent-if failed to observe/trace record of daily transactions. | X43: Regular
X44: Irregular
A45: What to look for | B45: =[5]Keys!A73 -> 3rd Party Opinion | C45: Positive, Respected | D45: Observation/ Justification | E45: she is well respected business woman | J45: =IF(C45=C85,D85,IF(C45=C86,D86,IF(C45=C87,D87))) -> 5 | K45: =IF(E45<>"","OK", "INVALID") -> OK | X45: None
B46: Positive/Respected-if positive feedback is received(if mentioned as reliable/dependable; responsible; hard-working; organized, honest). Moderate-if few negative feedback/ compliants received. | X46: Cooperative | Y46: 3.5
G47: Business and Character Maximum score | J47: 100 | X47: Hesitant | Y47: 2
G48: Achieved | J48: =IF(AND(OR(K45="invalid",K42="invalid",K39="invalid",K33="invalid",K30="invalid",K27="invalid",K24="invalid",K21="invalid",K18="invalid")),"INVALID",SUM(I13+J18+J21+J24+J27+J30+J33+J39+J42+J45)) -> 87 | X48: Uncooperative | Y48: 0 | Z48: Asset management
F49: =IF(G49="Borrower failed to pass qualitative assessment:DO NOT PROCEED",1,IF(G49="OK",3,"")) -> 3 | G49: =IF(AND(J48>75,J48<>"invalid"),"OK",D51) -> OK
...

Sheet (3)Cashflow Analysis
A1: CASHFLOW ANALYSIS SHEET
B2: (1) Sales and Purchases Summary
F3: Cash-% | G3: Credit-%
B4: Sales data entered | C4: Per day | E4: Sales | F4: 1 | G4: =100%-F4 -> 0
E5: Purchase | F5: 0.95 | G5: =100%-F5 -> 0.05 | I5: Ending Inventory
B6: Sales ((Ref. appication form ser. No 12.1) | C6: =C4 -> Per day | D6: Unit Price | E6: Total value-Annual | F6: Cash sales | G6: Credit sales | I6: stock-unit (refer appication form 11.2) | J6: stock-value
B7: (Major Items) | C7: Unit
B8: kurs | C8: 120 | D8: 45 | E8: =IF($C$4="Per day",C8*D8*360,IF($C$4="Per Week",C8*D8*52,C8*D8*12)) -> 1944000 | F8: =$F$4*E8 -> 1944000 | G8: =E8-F8 -> 0 | I8: 0 | J8: =I8*D8 -> 0
B9: msa erat | C9: 230 | D9: 140 | E9: =IF($C$4="Per day",C9*D9*360,IF($C$4="Per Week",C9*D9*52,C9*D9*12)) -> 11592000 | F9: =$F$4*E9 -> 11592000 | G9: =E9-F9 -> 0 | I9: 0 | J9: =I9*D9 -> 0
B10: metet | C10: 330 | D10: 30 | E10: =IF($C$4="Per day",C10*D10*360,IF($C$4="Per Week",C10*D10*52,C10*D10*12)) -> 3564000 | F10: =$F$4*E10 -> 3564000 | G10: =E10-F10 -> 0 | I10: 0 | J10: =I10*D10 -> 0
B11: tkus neger | C11: 200 | D11: 18 | E11: =IF($C$4="Per day",C11*D11*360,IF($C$4="Per Week",C11*D11*52,C11*D11*12)) -> 1296000 | F11: =$F$4*E11 -> 1296000 | G11: =E11-F11 -> 0 | I11: 0 | J11: =I11*D11 -> 0
E12: =IF($C$4="Per day",C12*D12*360,IF($C$4="Per Week",C12*D12*52,C12*D12*12)) -> 0 | F12: =$F$4*E12 -> 0 | G12: =E12-F12 -> 0 | I12: 0 | J12: =I12*D12 -> 0
E13: =IF($C$4="Per day",C13*D13*360,IF($C$4="Per Week",C13*D13*52,C13*D13*12)) -> 0 | F13: =$F$4*E13 -> 0 | G13: =E13-F13 -> 0 | I13: 0 | J13: =I13*D13 -> 0
E14: =IF($C$4="Per day",C14*D14*360,IF($C$4="Per Week",C14*D14*52,C14*D14*12)) -> 0 | F14: =$F$4*E14 -> 0 | G14: =E14-F14 -> 0 | J14: =I14*D14 -> 0
B15: Total | E15: =SUM(E8:E14) -> 18396000 | F15: =SUM(F8:F14) -> 18396000 | G15: =SUM(G8:G14) -> 0 | J15: =SUM(J8:J14) -> 0
B16: purchase data entered | C16: Per week
A17: Begging inventory (value) | B17: Purchases (Ref.Appication form ser.no. 12.2) | C17: =C16 -> Per week | D17: Price | E17: Total value | F17: Cash purchase | G17: Credit purchase | I17: Stock-unit (Ref.appication form 11.4) | J17: Stock-value
B18: bulk purchase teff | C18: 30 | D18: 6000 | E18: =IF($C$16="Per day",C18*D18*360,IF($C$16="Per Week",C18*D18*52,C18*D18*12)) -> 9360000 | F18: =$F$5*E18 -> 8892000 | G18: =E18-F18 -> 468000 | I18: =120000/6000 -> 20 | J18: =I18*D18 -> 120000
B19: suger | C19: 27 | D19: 3000 | E19: =IF($C$16="Per day",C19*D19*360,IF($C$16="Per Week",C19*D19*52,C19*D19*12)) -> 4212000 | F19: =$F$5*E19 -> 4001400 | G19: =E19-F19 -> 210600 | J19: =I19*D19 -> 0
B20: veg | E20: =IF($C$16="Per day",C20*D20*360,IF($C$16="Per Week",C20*D20*52,C20*D20*12)) -> 0 | F20: =$F$5*E20 -> 0 | G20: =E20-F20 -> 0 | J20: =I20*D20 -> 0
E21: =IF($C$16="Per day",C21*D21*360,IF($C$16="Per Week",C21*D21*52,C21*D21*12)) -> 0 | F21: =$F$5*E21 -> 0 | G21: =E21-F21 -> 0 | J21: =I21*D21 -> 0
E22: =IF($C$16="Per day",C22*D22*360,IF($C$16="Per Week",C22*D22*52,C22*D22*12)) -> 0 | F22: =$F$5*E22 -> 0 | G22: =E22-F22 -> 0 | J22: =I22*D22 -> 0
E23: =IF($C$16="Per day",C23*D23*360,IF($C$16="Per Week",C23*D23*52,C23*D23*12)) -> 0 | F23: =$F$5*E23 -> 0 | G23: =E23-F23 -> 0 | J23: =I23*D23 -> 0
E24: =IF($C$16="Per day",C24*D24*360,IF($C$16="Per Week",C24*D24*52,C24*D24*12)) -> 0 | F24: =$F$5*E24 -> 0 | G24: =E24-F24 -> 0 | J24: =I24*D24 -> 0
E25: =IF($C$16="Per day",C25*D25*360,IF($C$16="Per Week",C25*D25*52,C25*D25*12)) -> 0 | F25: =$F$5*E25 -> 0 | G25: =E25-F25 -> 0 | J25: =I25*D25 -> 0
A26: =SUM(A18:A25) -> 0 | B26: Total | C26: 0 | E26: =SUM(E18:E25) -> 13572000 | F26: =SUM(F18:F25) -> 12893400 | G26: =SUM(G18:G25) -> 678600 | J26: =SUM(J18:J25) -> 120000
G27: Work-in-progress | I27: Total value (Ref.appication form 11.3) | J27: Stock-value
J28: =I28 -> 0
J29: =G28 -> 0
J30: =I30 -> 0
I31: Total | J31: =SUM(J28:J30) -> 0
A33: (2) Income Statement - Historical and Projected -(Ref. Application form ser. No 12.1 to 12.3)
C34: Accrual basis | F34: Cash basis
C35: Historical | D35: BIRR | E35: Projected | F35: =C35 -> Historical | G35: =E35 -> Projected
C36: =C71 -> Estimation
B37: For 12 months ending: | C37: =B113 -> 45229 | E37: =EDATE(C37,12) -> 45595 | F37: =B113 -> 45229 | G37: =EDATE(F37,12) -> 45595
B39: Sales-Gross | C39: =E15 -> 18396000 | E39: =C39*D99 -> 18396000 | F39: =F15 -> 18396000 | G39: =F39*D99 -> 18396000
B40: VAT/TOT | C40: =IF(C39>=500000,C39/1.15*15%-(E26/1.15*15%),C39/1.1*10%) -> 629217.39 | E40: =IF(E39>=500000,E39/1.15*15%-(D100*(E26/1.15*15%)),E39/1.1*10%) -> 629217.39 | F40: =IF(F39>=500000,F39/1.15*15%-(F26/1.15*15%),F39/1.1*10%) -> 717730.43 | G40: =IF(G39>=500000,G39/1.15*15%-(D100*(F26/1.15*15%)),G39/1.1*10%) -> 717730.43
B41: Sales-Net | C41: =C39-C40 -> 17766783 | E41: =E39-E40 -> 17766783 | F41: =F39-F40 -> 17678270 | G41: =G39-G40 -> 17678270
B43: Other Expences: (refer appication form 9.3)
...

Sheet (4) E&S Assessment
B1: COMPLIANCE E&S REQUIREMENTS
A3: I | B3: Exposure to Excluded Activities | C3: Desired 'YES'Column | D3: Desired "NO" column | E3: Description where required | F3: Mitigations-planned/existing | G3: INSTRUCTIONS
A4: 1.1 | B4: Does or will the client carry out any activities listed on the List of Excluded Activities? If yes, the investment cannot proceed | D4: No
A5: 1.2 | B5: Are you the owner of the premise of business? | C5: Yes | G5: If yes, present proof that you are the owner of premise. (Note: This certificate is required to ensure that there are no disputes regarding ownership of premise). If no, enclose lease agreement as proof that you have legally rented the premise.
A6: 1.3 | B6: Would the proposed activity involve the displacement of people? | D6: No | G6: If yes, describe:
A7: 1.4 | B7: Is the proposed activity situated within the green area designated by the municipality? | D7: No | G7: If yes, describe:
A8: 1.5 | B8: Would the proposed project employ children under the age of 18? | D8: No
A9: 1.6 | B9: Were you provided assistance by the project staff in filling out this checklist? | C9: Yes
A10: 1.7 | B10: Name of the representative of the enterprise, function and contact details:
A11: II | B11: Description of Sub-Project
A12: 2.1 | B12: Provide a brief technical description of the sub-project.
A13: 2.2 | B13: Would the project utilize chemicals and pesticides? If so list the types of chemicals and pesticides used. | D13: No
A14: III | B14: Environmental aspects
A15: 3.1 | B15: Is there surface water bodies in the surroundings of the site? Please describe | D15: No | G15: Describe: • the nature of the water body (river, stream, spring, lake), • distance to site, • downstream/upstream the site
A16: 3.2 | B16: is there groundwater resources (well-fields) in the surroundings of the site. Please descibe if any. | D16: No | G16: State distance to site.
A17: 3.3 | B17: Would the sub-projects emit pollutants to the environment? If so, describe. | D17: No | E17: xxxxx | G17: If yes, how do you intend to reduce or avoid this emission?
A18: 3.4 | B18: Would the sub-project involve the removal/clearance of vegetation? | D18: No | G18: If yes, how do you intend to reduce, avoid or compensate for the vegetation loss
A19: 3.5 | B19: List the type of waste (solid and liquid, and hazardous and non-hazardous) that the sub-project will generate.
A20: 3.6 | B20: How do you plan to dispose of this waste?
A21: 3.7 | B21: Do you intend to have a waste minimization and disposal strategy? If so describe. | C21: Yes
A22: iv | B22: Occupational Health and Safety (OSH) aspects
A23: 4.1 | B23: Does the enterprise engage in manufacturing, processing and/or other labour intensive activities? Please describe | D23: No
A24: 4.2 | B24: Are there existing and/or anticipated Occupational Health and Safety Issues at the enterprise? Pls descibe | D24: No | G24: Describe the availability of: • fire protection equipments, • personal protective equipments, • sufficient lighting, • sufficient work space, • etc. If applicable, also describe the availability of and access to standard operation procedure by the employees.
A25: 4.3 | B25: What do you intend to do to reduce OHS issues at your enterprise?
A26: V | B26: Health Aspects
A27: 5.1 | B27: State the number of employees at your enterprise? Also describe the nature of work they do?
A28: 5.2 | B28: Are there sanitation and hygiene services at the enterprise? Please describe | C28: Yes | G28: Existence and number of: • Latrines, • Showers, Also state the existence of a drainage system for waste.
A29: VI | B29: E&S Risk Category | F29: State justification: | G29: State justification:
A30: 6.1 | B30: Low Risk | C30: 6 | D30: 9 | E30: >=80%
A31: 6.2 | B31: Medium Risk | C31: 4 | D31: 7 | E31: <80%
A32: 6.3 | B32: High Risk | C32: 3 | D32: 5 | E32: <60%
B33: [If High Risk, refer transaction to DBE’s Senior Social and Environmental Officer at the Special Fund Administration and Rural Financial Intermediation Programme Coordination Directorate]
A34: VIII | B34: Decision on eligibility (approval)
B35: Total number of "yes" or "No | C35: =COUNTIF(C4:C28,"Yes") -> 4 | D35: =COUNTIF(D4:D28,"No") -> 11
B36: Total number of factors rated | C36: 4 | D36: 11
B37: Percentage of "yes"or "N0"ratings | C37: =C35/$C$36 -> 1 | D37: =D35/$D$36 -> 1
B38: Recommendation: | D38: =IF(AND(C37>=80%,D35>=80%),"PASS",IF(AND(C37>=60%,D37>=60%)," PASS WITH ACCEPTABLE ACTION POINTS","REJECT")) -> PASS
B39: Reject
B40: Accept / reject with management decision
B41: Accept with Corrective Action Plan
...

Sheet (5)Collateral Worksheet
B1: COLLATERAL VALUATION Worksheet
E2: Loan product | F2: WEDP
B3: 1. Immovable Assets (Land/Buildings) | C3: Age | D3: Value Declared | E3: Estimated Market Value or Forced Sales Value | F3: Max guarantee possible
B4: Buildings/ commercial Houses | F4: =IF(F2="WEDP",100%,50%) -> 1
B5: Residential House
E10: =SUM(E4:E9) -> 0 | F10: =E10*F4 -> 0
B12: 2. Moveable Assets/Fixed Deposits | C12: Age | D12: Value Declared | E12: Estimated Market Value or Forced Sales Value or Sum Insured | F12: Max guarantee possible
B13: Vehicle | F13: =IF($F$2="WEDP",100%,50%) -> 1
B14: Machineries | F14: =IF($F$2="WEDP",100%,50%) -> 1
B15: Tractor | F15: =IF($F$2="WEDP",100%,50%) -> 1
B16: Combiner/ harvesting machine | F16: =IF($F$2="WEDP",100%,50%) -> 1
F17: =IF($F$2="WEDP",100%,50%) -> 1
F18: =IF($F$2="WEDP",100%,50%) -> 1
E19: =SUM(E13:E18) -> 0 | F19: =E13*F13+E14*F14+E15*F15+E16*F16+E17*F17+E18*F18 -> 0
B21: 3. Intangible assets/ securities/contracts | E21: Value | F21: Max guarantee possible
B22: Cash collaterla/ blocked savings accounts | F22: =IF($F$2="WEDP",100%,50%) -> 1
B23: Share certificate | F23: =IF($F$2="WEDP",100%,50%) -> 1
B24: Bonds | F24: =IF($F$2="WEDP",100%,50%) -> 1
B25: Sales contracts | F25: =IF($F$2="WEDP",100%,50%) -> 1
F26: =IF($F$2="WEDP",100%,50%) -> 1
F27: =IF($F$2="WEDP",100%,50%) -> 1
F28: =IF($F$2="WEDP",100%,50%) -> 1
F29: =IF($F$2="WEDP",100%,50%) -> 1
E30: =SUM(E22:E29) -> 0 | F30: =E22*F22+E23*F23+E24*F24+E25*F25+E26*F26+E27*F27+E28*F28+E29*F29 -> 0
B32: 4. Guarantors | C32: Monthly salary | D32: Max Monthly deductable | E32: Max. Portion | F32: Max guarantee possible
D33: =C33*$E$33 -> 0 | E33: 0.33
D34: =C34*$E$33 -> 0
D35: =C35*$E$33 -> 0
D36: =C36*$E$33 -> 0
D37: =SUM(D33:D36) -> 0 | F37: =D37*'(1)Basic Info and loan request'!C44 -> 0
B39: Total Collateral Value | C39: =F10+F19+F30+F37 -> 0
B40: Loan plus interest | C40: ='(7)Repayment Schedule'!C97 -> 1437814.1
B41: Collateral coverage | C41: =C39/C40 -> 0
B44: Notes/Observations:

Sheet (6)Summary and Decision Sheet
A1: SUMMARY AND DECISION SHEET
A2: Customer: | B2: ='(1)Basic Info and loan request'!C9 -> meron | C2: ='(1)Basic Info and loan request'!D9 -> dagne | E2: Business name: | F2: ='(1)Basic Info and loan request'!C3 -> tkus café and restourant | H2: ='(1)Basic Info and loan request'!B4 -> Loan Product | I2: ='(1)Basic Info and loan request'!C4 -> WEDP | J2: Credit Officer | K2: ='(1)Basic Info and loan request'!F3 -> kibret
J3: Branch Name | K3: ='(1)Basic Info and loan request'!F4 -> mekelle
A6: Summary of Request, Key Indicators & Client Assessment
A8: Business Name: | B8: =#REF! -> #REF! | E8: Requested | J8: Installment Amount | K8: =#REF! -> #REF!
A9: Client Name: | B9: ='(1)Basic Info and loan request'!C9 -> meron | D9: Amount | E9: =#REF! -> #REF! | J9: Annual loan repayment | K9: =#REF! -> #REF!
A10: Business sector: | B10: ='(1)Basic Info and loan request'!C31 -> Service | D10: Term (months) | E10: =#REF! -> #REF! | J10: Total due | K10: =#REF! -> #REF!
A11: Years in operation | D11: Rate | E11: =#REF! -> #REF! | J11: Instalments/yr. | K11: =#REF! -> #REF!
A12: Number of Previous Loans | B12: =#REF! -> #REF! | J12: Total no. of instalments | K12: =#REF! -> #REF!
A15: Date of Loan Application:
I17: Risk rating
A18: Key financial Indicators | C18: Before Loan | E18: After Loan | F18: Rating | G18: Weight | H18: Earned score | I18: Low | J18: Medium | K18: High
A19: Acid Test (Cash/ current liability) | C19: ='(3)Cashflow Analysis'!J79*B50/100 -> 0 | E19: ='(3)Cashflow Analysis'!L79*B50 -> 2.5510232 | F19: =IF(H19>=5,L61,L60) -> √ | G19: 10 | H19: =IF((E19+C19)/2>1,10,IF((E19+C19)/2>=0.75, 5,0)) -> 10 | I19: >1 | J19: 1 | K19: <1
A20: Debt to Equity Ratio | C20: ='(3)Cashflow Analysis'!J80*B50 -> -1.1540816 | E20: ='(3)Cashflow Analysis'!L80*B50 -> 0.72496053 | F20: =IF(H20>=5,$L$61,$L$60) -> √ | G20: 10 | H20: =IF((E20+C20)/2<=2,G20,IF((E20+C20)/2<=(80%*2),(60%*G20),0)) -> 10 | I20: < 2 | J20: 2 | K20: > 2
A21: Debt Service Ratio/ Repayment capacity (Net cashflow/ total debt repayment) | C21: ='(3)Cashflow Analysis'!J85*B50 -> 4.5370791 | E21: ='(3)Cashflow Analysis'!L85*B50 -> 6.1228196 | F21: =IF(H21>=15,$L$61,$L$60) -> √ | G21: 25 | H21: =IF((E21+C21)/2>=1.5,G21,IF((E21+C21)/2>=1.3,(70%*G21),IF((E21+C21)/2>1.2,40%*G21,0))) -> 25 | I21: > 1.5 | J21: 1.5 | K21: < 1.5
A22: Net operating cashflow/Total debt repayment | C22: ='(3)Cashflow Analysis'!J87*B50 -> 4.5370791 | E22: ='(3)Cashflow Analysis'!L87*B50 -> 4.5370791 | F22: =IF(H22>=20,$L$61,$L$60) -> √ | G22: 35 | H22: =IF((E22+C22)/2>=1.25,G22,IF((E22+C22)/2>=1.15,(80%*G22),0)) -> 35 | I22: >1.25 | J22: 1.15 | K22: <1.1
A23: Number of months with negative cashflow | C23: N/A | E23: =COUNTIF('(3)Cashflow Analysis'!B146:M146,"<0") -> 0 | F23: =IF(H23>=8,$L$61,$L$60) -> √ | G23: 15 | H23: =IF(E23<=2,G23,IF(E23<=3,(70%*G23),0)) -> 15 | I23: 0 | J23: 2 | K23: >3
A24: Net Profit margin | C24: ='(3)Cashflow Analysis'!J84*B50 -> 0.16149972 | E24: ='(3)Cashflow Analysis'!L84*B50 -> 0.16149972 | F24: =IF(H24>=3,$L$61,$L$60) -> √ | G24: 5 | H24: =IF((E24+C24)/2>=25%,G24,IF((E24+C24)/2>=20%,(80%*G24),IF((E24+C24)/2>=10%,70%*G24,0))) -> 3.5 | I24: >25% | J24: 0.2 | K24: <10%
E25: Average score | G25: =SUM(G19:G24) -> 100 | H25: =SUM(H19:H24) -> 98.5
A26: Business and Character Assessment | E26: Score
A27: Credit and Repayment History | C27: =IF(E27>=10, "Credit Worthy", IF(E27>=5, "Moderate", "No/Poor Credit History")) -> Credit Worthy | D27: =IF(E27>=10,3,IF(E28>=5,2,1)) -> 3 | E27: ='(2)Bus. and Character Assess.'!I13 -> 10 | F27: =IF(E27<0, "REJECT LOAN REQUEST AND DO NOT SPEND ANY MORE TIME IN ANALYSIS","")
A28: ='(2)Bus. and Character Assess.'!B18 -> Years of business operation (Ref. application form ser.no. 2.5 and loan application date) | C28: ='(2)Bus. and Character Assess.'!C18 -> > 24 months | D28: =IF(E28>5,3,IF(E28=5,2,1)) -> 3 | E28: ='(2)Bus. and Character Assess.'!J18 -> 10
A29: ='(2)Bus. and Character Assess.'!B21 -> Management Competence (Ref. application form ser.no. 5) | C29: ='(2)Bus. and Character Assess.'!C21 -> Competent/ well performing | D29: =IF(E29>5,3,IF(E29=5,2,1)) -> 3 | E29: ='(2)Bus. and Character Assess.'!J21 -> 15
A30: ='(2)Bus. and Character Assess.'!B24 -> Supplier quality (Ref. application form ser no. 7) | C30: ='(2)Bus. and Character Assess.'!C24 -> Satisfactory/ Adequate supply chain | D30: =IF(E30>5,3,IF(E30=5,2,1)) -> 3 | E30: ='(2)Bus. and Character Assess.'!J24 -> 9
A31: ='(2)Bus. and Character Assess.'!B27 -> Sales Prospects/ Market Suitability (Ref. application form ser.no. 8) | C31: ='(2)Bus. and Character Assess.'!C27 -> Very good/ High demand projection | D31: =IF(E31>5,3,IF(E31=5,2,1)) -> 3 | E31: ='(2)Bus. and Character Assess.'!J27 -> 15
A32: ='(2)Bus. and Character Assess.'!B30 -> Project plan (Preparation)-Ref. application form ser.no.3.1 to 3.8 | C32: ='(2)Bus. and Character Assess.'!C30 -> Well planned | D32: =IF(E32>5,3,IF(E32=5,2,1)) -> 3 | E32: ='(2)Bus. and Character Assess.'!J30 -> 10
A33: ='(2)Bus. and Character Assess.'!B33 -> Savings record-( (Ref. application form ser.no. 10 and 9) | C33: ='(2)Bus. and Character Assess.'!C33 -> Some savings habit | D33: =IF(E33>3,3,IF(E33=3,2,1)) -> 2 | E33: ='(2)Bus. and Character Assess.'!J33 -> 3
A34: ='(2)Bus. and Character Assess.'!B39 -> Responsiveness | C34: ='(2)Bus. and Character Assess.'!C39 -> Cooperative/shared all relevant info/doc | D34: =IF(E34=5,3,IF(E34=3,2,1)) -> 3 | E34: ='(2)Bus. and Character Assess.'!J39 -> 5
A35: ='(2)Bus. and Character Assess.'!B42 -> Record Keeping and asset management (Ref. Application Form ser.no.6) | C35: ='(2)Bus. and Character Assess.'!C42 -> Basic record keeping | D35: =IF(E35>5,3,IF(E35=5,2,1)) -> 2 | E35: ='(2)Bus. and Character Assess.'!J42 -> 5
A36: ='(2)Bus. and Character Assess.'!B45 -> 3rd Party Opinion | C36: ='(2)Bus. and Character Assess.'!C45 -> Positive, Respected | D36: =IF(E36=5,3,IF(E36=3,2,1)) -> 3 | E36: ='(2)Bus. and Character Assess.'!J45 -> 5
C37: Total score out of 100 | E37: =SUM(E27:E36) -> 87 | F37: =IF('(2)Bus. and Character Assess.'!J48="invalid","Assessment not well justified","")
A38: REPAYMENT CAPACITY ANALYSIS
A40: Total cash inflow-Annual | G40: Total Principal | H40: ='(7)Repayment Schedule'!C95 -> 1200000
D41: Annual loan payment | F41: ='(3)Cashflow Analysis'!O139*-1 -> -1200000 | G41: Total Interest | H41: ='(7)Repayment Schedule'!C96 -> 237814.14
A42: Net cash flows from operations | B42: ='(3)Cashflow Analysis'!O135*B50 -> 3261738.3 | G42: Total Due | H42: =SUM(H40:H41) -> 1437814.1
G43: Loan tenure (Months) | H43: ='(1)Basic Info and loan request'!C44 -> 24
A44: Net cashflows from other sources | B44: ='(3)Cashflow Analysis'!O144*B50 -> 1140000
D45: Max loan capacity | F45: =IF(B46>B42,B42*'(1)Basic Info and loan request'!C44/12*70%,B46*'(1)Basic Info and loan request'!C44/12*70%) -> 4566433.6
A46: Net cashflows from all sources | B46: =B42+B44 -> 4401738.3 | F46: =IF(F45>=H42,3,1) -> 3
A50: Confidence level | B50: 0.95 | D50: Environmental assessment | F50: Loan>200000
...

Sheet (7)Repayment Schedule
C1: AMORTIZATION SCHEDULE: EVEN INSTALLMENTS
D4: Starting Balance: | F4: =#REF! -> #REF!
D5: Annual Int. Rate: | F5: =#REF! -> #REF!
D6: Periodic Rate | F6: =(1+F5)^(1/C87)-1 -> #REF!
D7: Term (Months): | F7: =#REF! -> #REF!
D8: Interest Only: | F8: =#REF! -> #REF!
D9: Starting Date: | F9: =#REF! -> #REF!
A11: Pmt. # | B11: Date | C11: Starting Balance | D11: Payment | F11: Interest | G11: Principal | H11: Ending Balance
A12: 1 | B12: =F9+30 -> #REF! | C12: =F4 -> #REF! | D12: =SUM(IF(AND(A12>$F$8,H11>0.1),-PMT($F$6,$F$7-$F$8,$F$4,0),F12)) -> #REF! | F12: =$F$6*C12 -> #REF! | G12: =SUM(IF($A12>$F$8,D12-F12,0)) -> #REF! | H12: =SUM($C12-$G12) -> #REF!
A13: =($A12+1) -> 2 | B13: =B12+31 -> #REF! | C13: =H12 -> #REF! | D13: =SUM(IF(AND(A13>$F$8,H12>0.1),-PMT($F$6,$F$7-$F$8,$F$4,0),F13)) -> #REF! | F13: =$F$6*C13 -> #REF! | G13: =SUM(IF($A13>$F$8,D13-F13,0)) -> #REF! | H13: =SUM($C13-$G13) -> #REF!
A14: =($A13+1) -> 3 | B14: =B13+31 -> #REF! | C14: =H13 -> #REF! | D14: =SUM(IF(AND(A14>$F$8,H13>0.1),-PMT($F$6,$F$7-$F$8,$F$4,0),F14)) -> #REF! | F14: =$F$6*C14 -> #REF! | G14: =SUM(IF($A14>$F$8,D14-F14,0)) -> #REF! | H14: =SUM($C14-$G14) -> #REF!
A15: =($A14+1) -> 4 | B15: =B14+31 -> #REF! | C15: =H14 -> #REF! | D15: =SUM(IF(AND(A15>$F$8,H14>0.1),-PMT($F$6,$F$7-$F$8,$F$4,0),F15)) -> #REF! | F15: =$F$6*C15 -> #REF! | G15: =SUM(IF($A15>$F$8,D15-F15,0)) -> #REF! | H15: =SUM($C15-$G15) -> #REF!
A16: =($A15+1) -> 5 | B16: =B15+31 -> #REF! | C16: =H15 -> #REF! | D16: =SUM(IF(AND(A16>$F$8,H15>0.1),-PMT($F$6,$F$7-$F$8,$F$4,0),F16)) -> #REF! | F16: =$F$6*C16 -> #REF! | G16: =SUM(IF($A16>$F$8,D16-F16,0)) -> #REF! | H16: =SUM($C16-$G16) -> #REF!
A17: =($A16+1) -> 6 | B17: =B16+31 -> #REF! | C17: =H16 -> #REF! | D17: =SUM(IF(AND(A17>$F$8,H16>0.1),-PMT($F$6,$F$7-$F$8,$F$4,0),F17)) -> #REF! | F17: =$F$6*C17 -> #REF! | G17: =SUM(IF($A17>$F$8,D17-F17,0)) -> #REF! | H17: =SUM($C17-$G17) -> #REF!
A18: =($A17+1) -> 7 | B18: =B17+31 -> #REF! | C18: =H17 -> #REF! | D18: =SUM(IF(AND(A18>$F$8,H17>0.1),-PMT($F$6,$F$7-$F$8,$F$4,0),F18)) -> #REF! | F18: =$F$6*C18 -> #REF! | G18: =SUM(IF($A18>$F$8,D18-F18,0)) -> #REF! | H18: =SUM($C18-$G18) -> #REF!
A19: =($A18+1) -> 8 | B19: =B18+31 -> #REF! | C19: =H18 -> #REF! | D19: =SUM(IF(AND(A19>$F$8,H18>0.1),-PMT($F$6,$F$7-$F$8,$F$4,0),F19)) -> #REF! | F19: =$F$6*C19 -> #REF! | G19: =SUM(IF($A19>$F$8,D19-F19,0)) -> #REF! | H19: =SUM($C19-$G19) -> #REF!
A20: =($A19+1) -> 9 | B20: =B19+31 -> #REF! | C20: =H19 -> #REF! | D20: =SUM(IF(AND(A20>$F$8,H19>0.1),-PMT($F$6,$F$7-$F$8,$F$4,0),F20)) -> #REF! | F20: =$F$6*C20 -> #REF! | G20: =SUM(IF($A20>$F$8,D20-F20,0)) -> #REF! | H20: =SUM($C20-$G20) -> #REF!
A21: =($A20+1) -> 10 | B21: =B20+31 -> #REF! | C21: =H20 -> #REF! | D21: =SUM(IF(AND(A21>$F$8,H20>0.1),-PMT($F$6,$F$7-$F$8,$F$4,0),F21)) -> #REF! | F21: =$F$6*C21 -> #REF! | G21: =SUM(IF($A21>$F$8,D21-F21,0)) -> #REF! | H21: =SUM($C21-$G21) -> #REF!
A22: =($A21+1) -> 11 | B22: =B21+31 -> #REF! | C22: =H21 -> #REF! | D22: =SUM(IF(AND(A22>$F$8,H21>0.1),-PMT($F$6,$F$7-$F$8,$F$4,0),F22)) -> #REF! | F22: =$F$6*C22 -> #REF! | G22: =SUM(IF($A22>$F$8,D22-F22,0)) -> #REF! | H22: =SUM($C22-$G22) -> #REF!
A23: =($A22+1) -> 12 | B23: =B22+31 -> #REF! | C23: =H22 -> #REF! | D23: =SUM(IF(AND(A23>$F$8,H22>0.1),-PMT($F$6,$F$7-$F$8,$F$4,0),F23)) -> #REF! | F23: =$F$6*C23 -> #REF! | G23: =SUM(IF($A23>$F$8,D23-F23,0)) -> #REF! | H23: =SUM($C23-$G23) -> #REF!
A24: =($A23+1) -> 13 | B24: =B23+31 -> #REF! | C24: =H23 -> #REF! | D24: =SUM(IF(AND(A24>$F$8,H23>0.1),-PMT($F$6,$F$7-$F$8,$F$4,0),F24)) -> #REF! | F24: =$F$6*C24 -> #REF! | G24: =SUM(IF($A24>$F$8,D24-F24,0)) -> #REF! | H24: =SUM($C24-$G24) -> #REF!
... A71: =($A70+1) -> 60 | B71: =B70+31 -> #REF! | C71: =H70 -> #REF! | D71: =SUM(IF(AND(A71>$F$8,H70>0.1),-PMT($F$6,$F$7-$F$8,$F$4,0),F71)) -> #REF! | F71: =$F$6*C71 -> #REF! | G71: =SUM(IF($A71>$F$8,D71-F71,0)) -> #REF! | H71: =SUM($C71-$G71) -> #REF!
B72: Total | D72: =SUM(D12:D71) -> #REF! | F72: =SUM(F12:F71) -> #REF! | G72: =SUM(G12:G71) -> #REF! | H72: =SUM(H12:H71) -> #REF!
U74: Declininig basis
G75: Declining balance Amortization Schedule | N75: Flat Rate Amortization Schedule | V75: 1 | W75: 2 | X75: 3 | Y75: 4 | Z75: 5 | AA75: 6 | AB75: 7 | AC75: 8 | AD75: 9 | AE75: 10 | AF75: 11 | AG75: 12
T76: Bi-annual | U76: P | AA76: =I81 -> 41908.922 | AG76: =I82 -> 42537.556
U77: I | AA77: =J81 -> 18000 | AG77: =J82 -> 17371.366
B78: Loan Conditions | G78: Nbr. Inst. | H78: PMT Schedule Tool (PST) | N78: Nbr. Inst. | O78: Repayment Schedule | T78: Quarterly | U78: P | X78: =I81 -> 41908.922 | AA78: =I82 -> 42537.556 | AD78: =I83 -> 43175.62 | AG78: =I84 -> 43823.254
B79: Loan Amount | C79: ='(1)Basic Info and loan request'!C42 -> 1200000 | H79: Installment | I79: Principal | J79: Interest | K79: Balance | O79: Installment | P79: Principal | Q79: Interest | R79: Balance | U79: I | X79: =J81 -> 18000 | AA79: =J82 -> 17371.366 | AD79: =J83 -> 16733.303 | AG79: =J84 -> 16085.669
B80: Interest (annual) | C80: ='(1)Basic Info and loan request'!F42 -> 0.18 | F80: 0 | K80: =C79 -> 1200000 | M80: 0 | R80: =C79 -> 1200000 | T80: Monthly | U80: P | V80: =I81 -> 41908.922 | W80: =I82 -> 42537.556 | X80: =I83 -> 43175.62 | Y80: =I84 -> 43823.254 | Z80: =I85 -> 44480.603 | AA80: =I86 -> 45147.812 | AB80: =I87 -> 45825.029 | AC80: =I88 -> 46512.404 | AD80: =I89 -> 47210.09 | AE80: =I90 -> 47918.242 | AF80: =I91 -> 48637.015 | AG80: =I92 -> 49366.571
B81: Periodic Interest (monthly, quarterly,etc) | C81: ='(1)Basic Info and loan request'!F42/'(1)Basic Info and loan request'!F46 -> 0.015 | F81: =IF($C$84>=1,0,1+F80) -> 1 | G81: =IF(F81=0,"",IF($C$88>=F81,F81,"")) -> 1 | H81: =IF(G81<>"",$C$90,"") -> 59908.922 | I81: =IF(G81<>"", -PPMT($C$81,G81,$C$88,$C$79),"") -> 41908.922 | J81: =IF(G81<>"", -IPMT($C$81,G81,$C$88,$C$79),"") -> 18000 | K81: =IF(G81<>"",K80-I81,K80) -> 1158091.1 | M81: =IF($C$84>=1,0,1+M80) -> 1 | N81: =IF(M81=0,"",IF($C$88>=M81,M81,"")) -> 1 | O81: =IF(N81<>"",$D$90,"") -> 59000 | P81: =IF(N81<>"",$C$79/$C$88,"") -> 50000 | Q81: =IF(N81<>"",$C$79*$C$80/$C$87,"") -> 18000 | R81: =R80-P81 -> 1150000 | U81: I | V81: =J81 -> 18000 | W81: =J82 -> 17371.366 | X81: =J83 -> 16733.303 | Y81: =J84 -> 16085.669 | Z81: =J85 -> 15428.32 | AA81: =J86 -> 14761.111 | AB81: =J87 -> 14083.894 | AC81: =J88 -> 13396.518 | AD81: =J89 -> 12698.832 | AE81: =J90 -> 11990.681 | AF81: =J91 -> 11271.907 | AG81: =J92 -> 10542.352
B82: Interest calculation method | C82: ='(1)Basic Info and loan request'!F44 -> Declining | F82: =IF($C$84>=2,0,1+F81) -> 2 | G82: =IF(F82=0,"",IF($C$88>=F82,F82,"")) -> 2 | H82: =IF(G82<>"",$C$90,"") -> 59908.922 | I82: =IF(G82<>"", -PPMT($C$81,G82,$C$88,$C$79),"") -> 42537.556 | J82: =IF(G82<>"", -IPMT($C$81,G82,$C$88,$C$79),"") -> 17371.366 | K82: =IF(G82<>"",K81-I82,K81) -> 1115553.5 | M82: =IF($C$84>=2,0,1+M81) -> 2 | N82: =IF(M82=0,"",IF($C$88>=M82,M82,"")) -> 2 | O82: =IF(N82<>"",$D$90,"") -> 59000 | P82: =IF(N82<>"",$C$79/$C$88,"") -> 50000 | Q82: =IF(N82<>"",$C$79*$C$80/$C$87,"") -> 18000 | R82: =IF(N82<>"",R81-P82,R81) -> 1100000
B83: Term (months) | C83: ='(1)Basic Info and loan request'!C44 -> 24 | F83: =IF($C$84>=3,0,1+F82) -> 3 | G83: =IF(F83=0,"",IF($C$88>=F83,F83,"")) -> 3 | H83: =IF(G83<>"",$C$90,"") -> 59908.922 | I83: =IF(G83<>"", -PPMT($C$81,G83,$C$88,$C$79),"") -> 43175.62 | J83: =IF(G83<>"", -IPMT($C$81,G83,$C$88,$C$79),"") -> 16733.303 | K83: =IF(G83<>"",K82-I83,K82) -> 1072377.9 | M83: =IF($C$84>=3,0,1+M82) -> 3 | N83: =IF(M83=0,"",IF($C$88>=M83,M83,"")) -> 3 | O83: =IF(N83<>"",$D$90,"") -> 59000 | P83: =IF(N83<>"",$C$79/$C$88,"") -> 50000 | Q83: =IF(N83<>"",$C$79*$C$80/$C$87,"") -> 18000 | R83: =IF(N83<>"",R82-P83,R82) -> 1050000
B84: Grace (months) | C84: ='(1)Basic Info and loan request'!C48 -> 0 | F84: =IF($C$84>=4,0,1+F83) -> 4 | G84: =IF(F84=0,"",IF($C$88>=F84,F84,"")) -> 4 | H84: =IF(G84<>"",$C$90,"") -> 59908.922 | I84: =IF(G84<>"", -PPMT($C$81,G84,$C$88,$C$79),"") -> 43823.254 | J84: =IF(G84<>"", -IPMT($C$81,G84,$C$88,$C$79),"") -> 16085.669 | K84: =IF(G84<>"",K83-I84,K83) -> 1028554.6 | M84: =IF($C$84>=4,0,1+M83) -> 4 | N84: =IF(M84=0,"",IF($C$88>=M84,M84,"")) -> 4 | O84: =IF(N84<>"",$D$90,"") -> 59000 | P84: =IF(N84<>"",$C$79/$C$88,"") -> 50000 | Q84: =IF(N84<>"",$C$79*$C$80/$C$87,"") -> 18000 | R84: =IF(N84<>"",R83-P84,R83) -> 1000000 | U84: Flat basis
B85: Installment frequency | C85: ='(1)Basic Info and loan request'!F46 -> 12 | F85: =IF($C$84>=5,0,1+F84) -> 5 | G85: =IF(F85=0,"",IF($C$88>=F85,F85,"")) -> 5 | H85: =IF(G85<>"",$C$90,"") -> 59908.922 | I85: =IF(G85<>"", -PPMT($C$81,G85,$C$88,$C$79),"") -> 44480.603 | J85: =IF(G85<>"", -IPMT($C$81,G85,$C$88,$C$79),"") -> 15428.32 | K85: =IF(G85<>"",K84-I85,K84) -> 984074.05 | M85: =IF($C$84>=5,0,1+M84) -> 5 | N85: =IF(M85=0,"",IF($C$88>=M85,M85,"")) -> 5 | O85: =IF(N85<>"",$D$90,"") -> 59000 | P85: =IF(N85<>"",$C$79/$C$88,"") -> 50000 | Q85: =IF(N85<>"",$C$79*$C$80/$C$87,"") -> 18000 | R85: =IF(N85<>"",R84-P85,R84) -> 950000 | S85: =IF($C$84>=5,$C$84,"") | V85: 1 | W85: 2 | X85: 3 | Y85: 4 | Z85: 5 | AA85: 6 | AB85: 7 | AC85: 8 | AD85: 9 | AE85: 10 | AF85: 11 | AG85: 12
F86: =IF($C$84>=6,0,1+F85) -> 6 | G86: =IF(F86=0,"",IF($C$88>=F86,F86,"")) -> 6 | H86: =IF(G86<>"",$C$90,"") -> 59908.922 | I86: =IF(G86<>"", -PPMT($C$81,G86,$C$88,$C$79),"") -> 45147.812 | J86: =IF(G86<>"", -IPMT($C$81,G86,$C$88,$C$79),"") -> 14761.111 | K86: =IF(G86<>"",K85-I86,K85) -> 938926.23 | M86: =IF($C$84>=6,0,1+M85) -> 6 | N86: =IF(M86=0,"",IF($C$88>=M86,M86,"")) -> 6 | O86: =IF(N86<>"",$D$90,"") -> 59000 | P86: =IF(N86<>"",$C$79/$C$88,"") -> 50000 | Q86: =IF(N86<>"",$C$79*$C$80/$C$87,"") -> 18000 | R86: =IF(N86<>"",R85-P86,R85) -> 900000 | S86: =IF($C$84>=6,$C$84,"") | T86: Bi-annual | U86: P | AA86: =P81 -> 50000 | AG86: =P82 -> 50000
B87: Nr. Installments/yr | C87: ='(1)Basic Info and loan request'!F46 -> 12 | F87: =F86+1 -> 7 | G87: =IF(F87=0,"",IF($C$88>=F87,F87,"")) -> 7 | H87: =IF(G87<>"",$C$90,"") -> 59908.922 | I87: =IF(G87<>"", -PPMT($C$81,G87,$C$88,$C$79),"") -> 45825.029 | J87: =IF(G87<>"", -IPMT($C$81,G87,$C$88,$C$79),"") -> 14083.894 | K87: =IF(G87<>"",K86-I87,K86) -> 893101.2 | M87: =M86+1 -> 7 | N87: =IF(M87=0,"",IF($C$88>=M87,M87,"")) -> 7 | O87: =IF(N87<>"",$D$90,"") -> 59000 | P87: =IF(N87<>"",$C$79/$C$88,"") -> 50000 | Q87: =IF(N87<>"",$C$79*$C$80/$C$87,"") -> 18000 | R87: =IF(N87<>"",R86-P87,R86) -> 850000 | U87: I | AA87: =Q81 -> 18000 | AG87: =Q82 -> 18000
B88: Total no. of installemtns | C88: ='(1)Basic Info and loan request'!F48 -> 24 | F88: =F87+1 -> 8 | G88: =IF(F88=0,"",IF($C$88>=F88,F88,"")) -> 8 | H88: =IF(G88<>"",$C$90,"") -> 59908.922 | I88: =IF(G88<>"", -PPMT($C$81,G88,$C$88,$C$79),"") -> 46512.404 | J88: =IF(G88<>"", -IPMT($C$81,G88,$C$88,$C$79),"") -> 13396.518 | K88: =IF(G88<>"",K87-I88,K87) -> 846588.8 | M88: =M87+1 -> 8 | N88: =IF(M88=0,"",IF($C$88>=M88,M88,"")) -> 8 | O88: =IF(N88<>"",$D$90,"") -> 59000 | P88: =IF(N88<>"",$C$79/$C$88,"") -> 50000 | Q88: =IF(N88<>"",$C$79*$C$80/$C$87,"") -> 18000 | R88: =IF(N88<>"",R87-P88,R87) -> 800000 | T88: Quarterly | U88: P | V88: =IF('[2]CF Projected'!$C$11>=1,"",IF('[2]CF Projected'!$D$4=[2]Keys!$B$8,'(7)Repayment Schedule'!I91,"")) | W88: =IF('[2]CF Projected'!$C$11>=2,"",IF('[2]CF Projected'!$D$4=[2]Keys!$B$8,'(7)Repayment Schedule'!I$82,"")) | X88: =P81 -> 50000 | AA88: =P82 -> 50000 | AD88: =P83 -> 50000 | AG88: =P84 -> 50000
C89: Declining basis | D89: Flat basis | F89: =F88+1 -> 9 | G89: =IF(F89=0,"",IF($C$88>=F89,F89,"")) -> 9 | H89: =IF(G89<>"",$C$90,"") -> 59908.922 | I89: =IF(G89<>"", -PPMT($C$81,G89,$C$88,$C$79),"") -> 47210.09 | J89: =IF(G89<>"", -IPMT($C$81,G89,$C$88,$C$79),"") -> 12698.832 | K89: =IF(G89<>"",K88-I89,K88) -> 799378.71 | M89: =M88+1 -> 9 | N89: =IF(M89=0,"",IF($C$88>=M89,M89,"")) -> 9 | O89: =IF(N89<>"",$D$90,"") -> 59000 | P89: =IF(N89<>"",$C$79/$C$88,"") -> 50000 | Q89: =IF(N89<>"",$C$79*$C$80/$C$87,"") -> 18000 | R89: =IF(N89<>"",R88-P89,R88) -> 750000 | U89: I | X89: =Q81 -> 18000 | AA89: =Q82 -> 18000 | AD89: =Q83 -> 18000 | AG89: =Q84 -> 18000
B90: Installment amount | C90: =-PMT(C81,C88,C79) -> 59908.922 | D90: =(C79/C88)+(C80*C79)/C88 -> 59000 | F90: =F89+1 -> 10 | G90: =IF(F90=0,"",IF($C$88>=F90,F90,"")) -> 10 | H90: =IF(G90<>"",$C$90,"") -> 59908.922 | I90: =IF(G90<>"", -PPMT($C$81,G90,$C$88,$C$79),"") -> 47918.242 | J90: =IF(G90<>"", -IPMT($C$81,G90,$C$88,$C$79),"") -> 11990.681 | K90: =IF(G90<>"",K89-I90,K89) -> 751460.47 | M90: =M89+1 -> 10 | N90: =IF(M90=0,"",IF($C$88>=M90,M90,"")) -> 10 | O90: =IF(N90<>"",$D$90,"") -> 59000 | P90: =IF(N90<>"",$C$79/$C$88,"") -> 50000 | Q90: =IF(N90<>"",$C$79*$C$80/$C$87,"") -> 18000 | R90: =IF(N90<>"",R89-P90,R89) -> 700000 | T90: Monthly | U90: P | V90: =P81 -> 50000 | W90: =V90 -> 50000 | X90: =W90 -> 50000 | Y90: =X90 -> 50000 | Z90: =Y90 -> 50000 | AA90: =Z90 -> 50000 | AB90: =AA90 -> 50000 | AC90: =AB90 -> 50000 | AD90: =AC90 -> 50000 | ... AG90: =AF90 -> 50000
...

Sheet Loan Amortization Schedule
A1: Loan Amortization Schedule
B4: Enter values | H4: Loan summary
C5: Loan amount | D5: ='(7)Repayment Schedule'!C79 -> 1200000 | I5: Scheduled payment | J5: =IF(Values_Entered,-PMT(Interest_Rate/Num_Pmt_Per_Year,Loan_Years*Num_Pmt_Per_Year,Loan_Amount),"") -> 59908.922
C6: Annual interest rate | D6: ='(7)Repayment Schedule'!C80 -> 0.18 | I6: Scheduled number of payments | J6: =IF(Values_Entered,Loan_Years*Num_Pmt_Per_Year,"") -> 24
C7: Loan period in years | D7: 2 | I7: Actual number of payments | J7: =IF(Values_Entered,Number_of_Payments,"") -> 24
C8: Number of payments per year | D8: 12 | I8: Total early payments | J8: =IF(Values_Entered,SUMIF(Beg_Bal,">0",Extra_Pay),"") -> 0
C9: Start date of loan | D9: 44562 | I9: Total interest | J9: =IF(Values_Entered,SUMIF(Beg_Bal,">0",Int),"") -> 237814.14
C10: Optional extra payments
B12: Lender name:
A16: Pmt. No. | B16: Payment Date | C16: Beginning Balance | D16: Scheduled Payment | E16: Extra Payment | F16: Total Payment | G16: Principal | H16: Interest | I16: Ending Balance | J16: Cumulative Interest
A18: =IF(Values_Entered,1,"") -> 1 | B18: =IF(Pay_Num<>"",DATE(YEAR(Loan_Start),MONTH(Loan_Start)+(Pay_Num)*12/Num_Pmt_Per_Year,DAY(Loan_Start)),"") -> 44593 | C18: =IF(Values_Entered,Loan_Amount,"") -> 1200000 | D18: =IF(Pay_Num<>"",Scheduled_Monthly_Payment,"") -> 59908.922 | E18: =IF(AND(Pay_Num<>"",Sched_Pay+Scheduled_Extra_Payments<Beg_Bal),Scheduled_Extra_Payments,IF(AND(Pay_Num<>"",Beg_Bal-Sched_Pay>0),Beg_Bal-Sched_Pay,IF(Pay_Num<>"",0,""))) -> 0 | F18: =IF(AND(Pay_Num<>"",Sched_Pay+Extra_Pay<Beg_Bal),Sched_Pay+Extra_Pay,IF(Pay_Num<>"",Beg_Bal,"")) -> 59908.922 | G18: =IF(Pay_Num<>"",Total_Pay-Int,"") -> 41908.922 | H18: =IF(Pay_Num<>"",Beg_Bal*(Interest_Rate/Num_Pmt_Per_Year),"") -> 18000 | I18: =IF(AND(Pay_Num<>"",Sched_Pay+Extra_Pay<Beg_Bal),Beg_Bal-Princ,IF(Pay_Num<>"",0,"")) -> 1158091.1 | J18: =SUM($H$18:$H18) -> 18000
A19: =IF(Values_Entered,A18+1,"") -> 2 | B19: =IF(Pay_Num<>"",DATE(YEAR(Loan_Start),MONTH(Loan_Start)+(Pay_Num)*12/Num_Pmt_Per_Year,DAY(Loan_Start)),"") -> 44621 | C19: =IF(Pay_Num<>"",I18,"") -> 1158091.1 | D19: =IF(Pay_Num<>"",Scheduled_Monthly_Payment,"") -> 59908.922 | E19: =IF(AND(Pay_Num<>"",Sched_Pay+Scheduled_Extra_Payments<Beg_Bal),Scheduled_Extra_Payments,IF(AND(Pay_Num<>"",Beg_Bal-Sched_Pay>0),Beg_Bal-Sched_Pay,IF(Pay_Num<>"",0,""))) -> 0 | F19: =IF(AND(Pay_Num<>"",Sched_Pay+Extra_Pay<Beg_Bal),Sched_Pay+Extra_Pay,IF(Pay_Num<>"",Beg_Bal,"")) -> 59908.922 | G19: =IF(Pay_Num<>"",Total_Pay-Int,"") -> 42537.556 | H19: =IF(Pay_Num<>"",Beg_Bal*Interest_Rate/Num_Pmt_Per_Year,"") -> 17371.366 | I19: =IF(AND(Pay_Num<>"",Sched_Pay+Extra_Pay<Beg_Bal),Beg_Bal-Princ,IF(Pay_Num<>"",0,"")) -> 1115553.5 | J19: =SUM($H$18:$H19) -> 35371.366
A20: =IF(Values_Entered,A19+1,"") -> 3 | B20: =IF(Pay_Num<>"",DATE(YEAR(Loan_Start),MONTH(Loan_Start)+(Pay_Num)*12/Num_Pmt_Per_Year,DAY(Loan_Start)),"") -> 44652 | C20: =IF(Pay_Num<>"",I19,"") -> 1115553.5 | D20: =IF(Pay_Num<>"",Scheduled_Monthly_Payment,"") -> 59908.922 | E20: =IF(AND(Pay_Num<>"",Sched_Pay+Scheduled_Extra_Payments<Beg_Bal),Scheduled_Extra_Payments,IF(AND(Pay_Num<>"",Beg_Bal-Sched_Pay>0),Beg_Bal-Sched_Pay,IF(Pay_Num<>"",0,""))) -> 0 | F20: =IF(AND(Pay_Num<>"",Sched_Pay+Extra_Pay<Beg_Bal),Sched_Pay+Extra_Pay,IF(Pay_Num<>"",Beg_Bal,"")) -> 59908.922 | G20: =IF(Pay_Num<>"",Total_Pay-Int,"") -> 43175.62 | H20: =IF(Pay_Num<>"",Beg_Bal*Interest_Rate/Num_Pmt_Per_Year,"") -> 16733.303 | I20: =IF(AND(Pay_Num<>"",Sched_Pay+Extra_Pay<Beg_Bal),Beg_Bal-Princ,IF(Pay_Num<>"",0,"")) -> 1072377.9 | J20: =SUM($H$18:$H20) -> 52104.669
A21: =IF(Values_Entered,A20+1,"") -> 4 | B21: =IF(Pay_Num<>"",DATE(YEAR(Loan_Start),MONTH(Loan_Start)+(Pay_Num)*12/Num_Pmt_Per_Year,DAY(Loan_Start)),"") -> 44682 | C21: =IF(Pay_Num<>"",I20,"") -> 1072377.9 | D21: =IF(Pay_Num<>"",Scheduled_Monthly_Payment,"") -> 59908.922 | E21: =IF(AND(Pay_Num<>"",Sched_Pay+Scheduled_Extra_Payments<Beg_Bal),Scheduled_Extra_Payments,IF(AND(Pay_Num<>"",Beg_Bal-Sched_Pay>0),Beg_Bal-Sched_Pay,IF(Pay_Num<>"",0,""))) -> 0 | F21: =IF(AND(Pay_Num<>"",Sched_Pay+Extra_Pay<Beg_Bal),Sched_Pay+Extra_Pay,IF(Pay_Num<>"",Beg_Bal,"")) -> 59908.922 | G21: =IF(Pay_Num<>"",Total_Pay-Int,"") -> 43823.254 | H21: =IF(Pay_Num<>"",Beg_Bal*Interest_Rate/Num_Pmt_Per_Year,"") -> 16085.669 | I21: =IF(AND(Pay_Num<>"",Sched_Pay+Extra_Pay<Beg_Bal),Beg_Bal-Princ,IF(Pay_Num<>"",0,"")) -> 1028554.6 | J21: =SUM($H$18:$H21) -> 68190.338
A22: =IF(Values_Entered,A21+1,"") -> 5 | B22: =IF(Pay_Num<>"",DATE(YEAR(Loan_Start),MONTH(Loan_Start)+(Pay_Num)*12/Num_Pmt_Per_Year,DAY(Loan_Start)),"") -> 44713 | C22: =IF(Pay_Num<>"",I21,"") -> 1028554.6 | D22: =IF(Pay_Num<>"",Scheduled_Monthly_Payment,"") -> 59908.922 | E22: =IF(AND(Pay_Num<>"",Sched_Pay+Scheduled_Extra_Payments<Beg_Bal),Scheduled_Extra_Payments,IF(AND(Pay_Num<>"",Beg_Bal-Sched_Pay>0),Beg_Bal-Sched_Pay,IF(Pay_Num<>"",0,""))) -> 0 | F22: =IF(AND(Pay_Num<>"",Sched_Pay+Extra_Pay<Beg_Bal),Sched_Pay+Extra_Pay,IF(Pay_Num<>"",Beg_Bal,"")) -> 59908.922 | G22: =IF(Pay_Num<>"",Total_Pay-Int,"") -> 44480.603 | H22: =IF(Pay_Num<>"",Beg_Bal*Interest_Rate/Num_Pmt_Per_Year,"") -> 15428.32 | I22: =IF(AND(Pay_Num<>"",Sched_Pay+Extra_Pay<Beg_Bal),Beg_Bal-Princ,IF(Pay_Num<>"",0,"")) -> 984074.05 | J22: =SUM($H$18:$H22) -> 83618.657
A23: =IF(Values_Entered,A22+1,"") -> 6 | B23: =IF(Pay_Num<>"",DATE(YEAR(Loan_Start),MONTH(Loan_Start)+(Pay_Num)*12/Num_Pmt_Per_Year,DAY(Loan_Start)),"") -> 44743 | C23: =IF(Pay_Num<>"",I22,"") -> 984074.05 | D23: =IF(Pay_Num<>"",Scheduled_Monthly_Payment,"") -> 59908.922 | E23: =IF(AND(Pay_Num<>"",Sched_Pay+Scheduled_Extra_Payments<Beg_Bal),Scheduled_Extra_Payments,IF(AND(Pay_Num<>"",Beg_Bal-Sched_Pay>0),Beg_Bal-Sched_Pay,IF(Pay_Num<>"",0,""))) -> 0 | F23: =IF(AND(Pay_Num<>"",Sched_Pay+Extra_Pay<Beg_Bal),Sched_Pay+Extra_Pay,IF(Pay_Num<>"",Beg_Bal,"")) -> 59908.922 | G23: =IF(Pay_Num<>"",Total_Pay-Int,"") -> 45147.812 | H23: =IF(Pay_Num<>"",Beg_Bal*Interest_Rate/Num_Pmt_Per_Year,"") -> 14761.111 | I23: =IF(AND(Pay_Num<>"",Sched_Pay+Extra_Pay<Beg_Bal),Beg_Bal-Princ,IF(Pay_Num<>"",0,"")) -> 938926.23 | J23: =SUM($H$18:$H23) -> 98379.768
A24: =IF(Values_Entered,A23+1,"") -> 7 | B24: =IF(Pay_Num<>"",DATE(YEAR(Loan_Start),MONTH(Loan_Start)+(Pay_Num)*12/Num_Pmt_Per_Year,DAY(Loan_Start)),"") -> 44774 | C24: =IF(Pay_Num<>"",I23,"") -> 938926.23 | D24: =IF(Pay_Num<>"",Scheduled_Monthly_Payment,"") -> 59908.922 | E24: =IF(AND(Pay_Num<>"",Sched_Pay+Scheduled_Extra_Payments<Beg_Bal),Scheduled_Extra_Payments,IF(AND(Pay_Num<>"",Beg_Bal-Sched_Pay>0),Beg_Bal-Sched_Pay,IF(Pay_Num<>"",0,""))) -> 0 | F24: =IF(AND(Pay_Num<>"",Sched_Pay+Extra_Pay<Beg_Bal),Sched_Pay+Extra_Pay,IF(Pay_Num<>"",Beg_Bal,"")) -> 59908.922 | G24: =IF(Pay_Num<>"",Total_Pay-Int,"") -> 45825.029 | H24: =IF(Pay_Num<>"",Beg_Bal*Interest_Rate/Num_Pmt_Per_Year,"") -> 14083.894 | I24: =IF(AND(Pay_Num<>"",Sched_Pay+Extra_Pay<Beg_Bal),Beg_Bal-Princ,IF(Pay_Num<>"",0,"")) -> 893101.2 | J24: =SUM($H$18:$H24) -> 112463.66
A25: =IF(Values_Entered,A24+1,"") -> 8 | B25: =IF(Pay_Num<>"",DATE(YEAR(Loan_Start),MONTH(Loan_Start)+(Pay_Num)*12/Num_Pmt_Per_Year,DAY(Loan_Start)),"") -> 44805 | C25: =IF(Pay_Num<>"",I24,"") -> 893101.2 | D25: =IF(Pay_Num<>"",Scheduled_Monthly_Payment,"") -> 59908.922 | E25: =IF(AND(Pay_Num<>"",Sched_Pay+Scheduled_Extra_Payments<Beg_Bal),Scheduled_Extra_Payments,IF(AND(Pay_Num<>"",Beg_Bal-Sched_Pay>0),Beg_Bal-Sched_Pay,IF(Pay_Num<>"",0,""))) -> 0 | F25: =IF(AND(Pay_Num<>"",Sched_Pay+Extra_Pay<Beg_Bal),Sched_Pay+Extra_Pay,IF(Pay_Num<>"",Beg_Bal,"")) -> 59908.922 | G25: =IF(Pay_Num<>"",Total_Pay-Int,"") -> 46512.404 | H25: =IF(Pay_Num<>"",Beg_Bal*Interest_Rate/Num_Pmt_Per_Year,"") -> 13396.518 | I25: =IF(AND(Pay_Num<>"",Sched_Pay+Extra_Pay<Beg_Bal),Beg_Bal-Princ,IF(Pay_Num<>"",0,"")) -> 846588.8 | J25: =SUM($H$18:$H25) -> 125860.18
A26: =IF(Values_Entered,A25+1,"") -> 9 | B26: =IF(Pay_Num<>"",DATE(YEAR(Loan_Start),MONTH(Loan_Start)+(Pay_Num)*12/Num_Pmt_Per_Year,DAY(Loan_Start)),"") -> 44835 | C26: =IF(Pay_Num<>"",I25,"") -> 846588.8 | D26: =IF(Pay_Num<>"",Scheduled_Monthly_Payment,"") -> 59908.922 | E26: =IF(AND(Pay_Num<>"",Sched_Pay+Scheduled_Extra_Payments<Beg_Bal),Scheduled_Extra_Payments,IF(AND(Pay_Num<>"",Beg_Bal-Sched_Pay>0),Beg_Bal-Sched_Pay,IF(Pay_Num<>"",0,""))) -> 0 | F26: =IF(AND(Pay_Num<>"",Sched_Pay+Extra_Pay<Beg_Bal),Sched_Pay+Extra_Pay,IF(Pay_Num<>"",Beg_Bal,"")) -> 59908.922 | G26: =IF(Pay_Num<>"",Total_Pay-Int,"") -> 47210.09 | H26: =IF(Pay_Num<>"",Beg_Bal*Interest_Rate/Num_Pmt_Per_Year,"") -> 12698.832 | I26: =IF(AND(Pay_Num<>"",Sched_Pay+Extra_Pay<Beg_Bal),Beg_Bal-Princ,IF(Pay_Num<>"",0,"")) -> 799378.71 | J26: =SUM($H$18:$H26) -> 138559.01
A27: =IF(Values_Entered,A26+1,"") -> 10 | B27: =IF(Pay_Num<>"",DATE(YEAR(Loan_Start),MONTH(Loan_Start)+(Pay_Num)*12/Num_Pmt_Per_Year,DAY(Loan_Start)),"") -> 44866 | C27: =IF(Pay_Num<>"",I26,"") -> 799378.71 | D27: =IF(Pay_Num<>"",Scheduled_Monthly_Payment,"") -> 59908.922 | E27: =IF(AND(Pay_Num<>"",Sched_Pay+Scheduled_Extra_Payments<Beg_Bal),Scheduled_Extra_Payments,IF(AND(Pay_Num<>"",Beg_Bal-Sched_Pay>0),Beg_Bal-Sched_Pay,IF(Pay_Num<>"",0,""))) -> 0 | F27: =IF(AND(Pay_Num<>"",Sched_Pay+Extra_Pay<Beg_Bal),Sched_Pay+Extra_Pay,IF(Pay_Num<>"",Beg_Bal,"")) -> 59908.922 | G27: =IF(Pay_Num<>"",Total_Pay-Int,"") -> 47918.242 | H27: =IF(Pay_Num<>"",Beg_Bal*Interest_Rate/Num_Pmt_Per_Year,"") -> 11990.681 | I27: =IF(AND(Pay_Num<>"",Sched_Pay+Extra_Pay<Beg_Bal),Beg_Bal-Princ,IF(Pay_Num<>"",0,"")) -> 751460.47 | J27: =SUM($H$18:$H27) -> 150549.69
